<?xml version="1.0"?>
<robot xmlns:xacro="http://ros.org/wiki/xacro" name="noah_wheel">

	<xacro:macro name="noah_wheel" params="wheel_prefix wheel_length wheel_radius parent_link *joint_pose">

		<xacro:property name="M_PI" value="3.14159"/>

		<!-- Wheel description -->
		<link name="${wheel_prefix}_wheel_link">

			<inertial>
				<mass value="0.185" />
				<!-- Taken as solid cylinder -->
				<origin xyz="0 0 0" rpy="${M_PI/2} 0 0" />
				<inertia ixx="0.000121792" ixy="0" ixz="0" iyy="0.000121792" iyz="0" izz="0.00023125" />
			</inertial>

			<visual>
				<origin xyz="0 0 0" rpy="${M_PI/2} 0 0" />
				<geometry>					<!-- Meshes taken from husky robot -->
					<!--<mesh filename="package://noah_description/meshes/wheel_mesh.dae" />-->
					<cylinder length="${wheel_length}" radius="${wheel_radius}" />
				</geometry>
				<material name="black" />
			</visual>
			<collision>
				<origin xyz="0 0 0" rpy="${M_PI/2} 0 0" />
				<geometry>
					<cylinder length="${wheel_length}" radius="${wheel_radius}" />
				</geometry>
			</collision>

		</link>

		<!-- Wheel joint, where the wheel is attached. Should specify parent link and position in parent link -->
		<joint name="${wheel_prefix}_wheel_joint" type="continuous">
			<parent link="${parent_link}" />
			<child link="${wheel_prefix}_wheel_link" />
			<xacro:insert_block name="joint_pose"/>
			<axis xyz="0 1 0" />
		</joint>

		<!-- Wheels gazebo properties -->
		<gazebo reference="${wheel_prefix}_wheel_link">
			<mu1 value="1.0"/>
			<mu2 value="1.0"/>
			<kp value="10000000.0" />
			<kd value="1.0" />
			<fdir1 value="1 0 0"/>
			<material>Gazebo/Black</material>
		</gazebo>

	</xacro:macro>

</robot>
